Traceback (most recent call last):
  File "/root/Doopliss/main.py", line 11, in <module>
    import discord
ModuleNotFoundError: No module named 'discord'
Traceback (most recent call last):
  File "/root/Doopliss/main.py", line 11, in <module>
    import discord
ModuleNotFoundError: No module named 'discord'
Traceback (most recent call last):
  File "/root/Doopliss/main.py", line 11, in <module>
    import discord
ModuleNotFoundError: No module named 'discord'
Traceback (most recent call last):
  File "/root/Doopliss/main.py", line 11, in <module>
    import discord
ModuleNotFoundError: No module named 'discord'
Traceback (most recent call last):
  File "/root/Doopliss/main.py", line 11, in <module>
    import discord
ModuleNotFoundError: No module named 'discord'
Traceback (most recent call last):
  File "/root/Doopliss/main.py", line 11, in <module>
    import discord
ModuleNotFoundError: No module named 'discord'
Traceback (most recent call last):
  File "/root/Doopliss/main.py", line 11, in <module>
    import discord
ModuleNotFoundError: No module named 'discord'
Traceback (most recent call last):
  File "/root/Doopliss/main.py", line 11, in <module>
    import discord
ModuleNotFoundError: No module named 'discord'
Traceback (most recent call last):
  File "/usr/local/lib/python3.10/dist-packages/discord/http.py", line 406, in static_login
    data = await self.request(Route("GET", "/users/@me"))
  File "/usr/local/lib/python3.10/dist-packages/discord/http.py", line 359, in request
    raise HTTPException(response, data)
discord.errors.HTTPException: 401 Unauthorized (error code: 0): 401: Unauthorized

The above exception was the direct cause of the following exception:

Traceback (most recent call last):
  File "/root/Doopliss/main.py", line 60, in <module>
    bot.run(TOKEN)
  File "/usr/local/lib/python3.10/dist-packages/discord/client.py", line 717, in run
    return future.result()
  File "/usr/local/lib/python3.10/dist-packages/discord/client.py", line 696, in runner
    await self.start(*args, **kwargs)
  File "/usr/local/lib/python3.10/dist-packages/discord/client.py", line 659, in start
    await self.login(token)
  File "/usr/local/lib/python3.10/dist-packages/discord/client.py", line 514, in login
    data = await self.http.static_login(token.strip())
  File "/usr/local/lib/python3.10/dist-packages/discord/http.py", line 410, in static_login
    raise LoginFailure("Improper token has been passed.") from exc
discord.errors.LoginFailure: Improper token has been passed.
Traceback (most recent call last):
  File "/usr/local/lib/python3.10/dist-packages/discord/http.py", line 406, in static_login
    data = await self.request(Route("GET", "/users/@me"))
  File "/usr/local/lib/python3.10/dist-packages/discord/http.py", line 359, in request
    raise HTTPException(response, data)
discord.errors.HTTPException: 401 Unauthorized (error code: 0): 401: Unauthorized

The above exception was the direct cause of the following exception:

Traceback (most recent call last):
  File "/root/Doopliss/main.py", line 60, in <module>
    bot.run(TOKEN)
  File "/usr/local/lib/python3.10/dist-packages/discord/client.py", line 717, in run
    return future.result()
  File "/usr/local/lib/python3.10/dist-packages/discord/client.py", line 696, in runner
    await self.start(*args, **kwargs)
  File "/usr/local/lib/python3.10/dist-packages/discord/client.py", line 659, in start
    await self.login(token)
  File "/usr/local/lib/python3.10/dist-packages/discord/client.py", line 514, in login
    data = await self.http.static_login(token.strip())
  File "/usr/local/lib/python3.10/dist-packages/discord/http.py", line 410, in static_login
    raise LoginFailure("Improper token has been passed.") from exc
discord.errors.LoginFailure: Improper token has been passed.
Traceback (most recent call last):
  File "/usr/local/lib/python3.10/dist-packages/discord/http.py", line 406, in static_login
    data = await self.request(Route("GET", "/users/@me"))
  File "/usr/local/lib/python3.10/dist-packages/discord/http.py", line 359, in request
    raise HTTPException(response, data)
discord.errors.HTTPException: 401 Unauthorized (error code: 0): 401: Unauthorized

The above exception was the direct cause of the following exception:

Traceback (most recent call last):
  File "/root/Doopliss/main.py", line 60, in <module>
    bot.run(TOKEN)
  File "/usr/local/lib/python3.10/dist-packages/discord/client.py", line 717, in run
    return future.result()
  File "/usr/local/lib/python3.10/dist-packages/discord/client.py", line 696, in runner
    await self.start(*args, **kwargs)
  File "/usr/local/lib/python3.10/dist-packages/discord/client.py", line 659, in start
    await self.login(token)
  File "/usr/local/lib/python3.10/dist-packages/discord/client.py", line 514, in login
    data = await self.http.static_login(token.strip())
  File "/usr/local/lib/python3.10/dist-packages/discord/http.py", line 410, in static_login
    raise LoginFailure("Improper token has been passed.") from exc
discord.errors.LoginFailure: Improper token has been passed.
Traceback (most recent call last):
  File "/usr/local/lib/python3.10/dist-packages/discord/http.py", line 406, in static_login
    data = await self.request(Route("GET", "/users/@me"))
  File "/usr/local/lib/python3.10/dist-packages/discord/http.py", line 359, in request
    raise HTTPException(response, data)
discord.errors.HTTPException: 401 Unauthorized (error code: 0): 401: Unauthorized

The above exception was the direct cause of the following exception:

Traceback (most recent call last):
  File "/root/Doopliss/main.py", line 60, in <module>
    bot.run(TOKEN)
  File "/usr/local/lib/python3.10/dist-packages/discord/client.py", line 717, in run
    return future.result()
  File "/usr/local/lib/python3.10/dist-packages/discord/client.py", line 696, in runner
    await self.start(*args, **kwargs)
  File "/usr/local/lib/python3.10/dist-packages/discord/client.py", line 659, in start
    await self.login(token)
  File "/usr/local/lib/python3.10/dist-packages/discord/client.py", line 514, in login
    data = await self.http.static_login(token.strip())
  File "/usr/local/lib/python3.10/dist-packages/discord/http.py", line 410, in static_login
    raise LoginFailure("Improper token has been passed.") from exc
discord.errors.LoginFailure: Improper token has been passed.
Traceback (most recent call last):
  File "/usr/local/lib/python3.10/dist-packages/discord/http.py", line 406, in static_login
    data = await self.request(Route("GET", "/users/@me"))
  File "/usr/local/lib/python3.10/dist-packages/discord/http.py", line 359, in request
    raise HTTPException(response, data)
discord.errors.HTTPException: 401 Unauthorized (error code: 0): 401: Unauthorized

The above exception was the direct cause of the following exception:

Traceback (most recent call last):
  File "/root/Doopliss/main.py", line 60, in <module>
    bot.run(TOKEN)
  File "/usr/local/lib/python3.10/dist-packages/discord/client.py", line 717, in run
    return future.result()
  File "/usr/local/lib/python3.10/dist-packages/discord/client.py", line 696, in runner
    await self.start(*args, **kwargs)
  File "/usr/local/lib/python3.10/dist-packages/discord/client.py", line 659, in start
    await self.login(token)
  File "/usr/local/lib/python3.10/dist-packages/discord/client.py", line 514, in login
    data = await self.http.static_login(token.strip())
  File "/usr/local/lib/python3.10/dist-packages/discord/http.py", line 410, in static_login
    raise LoginFailure("Improper token has been passed.") from exc
discord.errors.LoginFailure: Improper token has been passed.
Traceback (most recent call last):
  File "/usr/local/lib/python3.10/dist-packages/discord/http.py", line 406, in static_login
    data = await self.request(Route("GET", "/users/@me"))
  File "/usr/local/lib/python3.10/dist-packages/discord/http.py", line 359, in request
    raise HTTPException(response, data)
discord.errors.HTTPException: 401 Unauthorized (error code: 0): 401: Unauthorized

The above exception was the direct cause of the following exception:

Traceback (most recent call last):
  File "/root/Doopliss/main.py", line 60, in <module>
    bot.run(TOKEN)
  File "/usr/local/lib/python3.10/dist-packages/discord/client.py", line 717, in run
    return future.result()
  File "/usr/local/lib/python3.10/dist-packages/discord/client.py", line 696, in runner
    await self.start(*args, **kwargs)
  File "/usr/local/lib/python3.10/dist-packages/discord/client.py", line 659, in start
    await self.login(token)
  File "/usr/local/lib/python3.10/dist-packages/discord/client.py", line 514, in login
    data = await self.http.static_login(token.strip())
  File "/usr/local/lib/python3.10/dist-packages/discord/http.py", line 410, in static_login
    raise LoginFailure("Improper token has been passed.") from exc
discord.errors.LoginFailure: Improper token has been passed.
Traceback (most recent call last):
  File "/usr/local/lib/python3.10/dist-packages/discord/http.py", line 406, in static_login
    data = await self.request(Route("GET", "/users/@me"))
  File "/usr/local/lib/python3.10/dist-packages/discord/http.py", line 359, in request
    raise HTTPException(response, data)
discord.errors.HTTPException: 401 Unauthorized (error code: 0): 401: Unauthorized

The above exception was the direct cause of the following exception:

Traceback (most recent call last):
  File "/root/Doopliss/main.py", line 60, in <module>
    bot.run(TOKEN)
  File "/usr/local/lib/python3.10/dist-packages/discord/client.py", line 717, in run
    return future.result()
  File "/usr/local/lib/python3.10/dist-packages/discord/client.py", line 696, in runner
    await self.start(*args, **kwargs)
  File "/usr/local/lib/python3.10/dist-packages/discord/client.py", line 659, in start
    await self.login(token)
  File "/usr/local/lib/python3.10/dist-packages/discord/client.py", line 514, in login
    data = await self.http.static_login(token.strip())
  File "/usr/local/lib/python3.10/dist-packages/discord/http.py", line 410, in static_login
    raise LoginFailure("Improper token has been passed.") from exc
discord.errors.LoginFailure: Improper token has been passed.
Traceback (most recent call last):
  File "/usr/local/lib/python3.10/dist-packages/discord/http.py", line 406, in static_login
    data = await self.request(Route("GET", "/users/@me"))
  File "/usr/local/lib/python3.10/dist-packages/discord/http.py", line 359, in request
    raise HTTPException(response, data)
discord.errors.HTTPException: 401 Unauthorized (error code: 0): 401: Unauthorized

The above exception was the direct cause of the following exception:

Traceback (most recent call last):
  File "/root/Doopliss/main.py", line 60, in <module>
    bot.run(TOKEN)
  File "/usr/local/lib/python3.10/dist-packages/discord/client.py", line 717, in run
    return future.result()
  File "/usr/local/lib/python3.10/dist-packages/discord/client.py", line 696, in runner
    await self.start(*args, **kwargs)
  File "/usr/local/lib/python3.10/dist-packages/discord/client.py", line 659, in start
    await self.login(token)
  File "/usr/local/lib/python3.10/dist-packages/discord/client.py", line 514, in login
    data = await self.http.static_login(token.strip())
  File "/usr/local/lib/python3.10/dist-packages/discord/http.py", line 410, in static_login
    raise LoginFailure("Improper token has been passed.") from exc
discord.errors.LoginFailure: Improper token has been passed.
Traceback (most recent call last):
  File "/usr/local/lib/python3.10/dist-packages/discord/http.py", line 406, in static_login
    data = await self.request(Route("GET", "/users/@me"))
  File "/usr/local/lib/python3.10/dist-packages/discord/http.py", line 359, in request
    raise HTTPException(response, data)
discord.errors.HTTPException: 401 Unauthorized (error code: 0): 401: Unauthorized

The above exception was the direct cause of the following exception:

Traceback (most recent call last):
  File "/root/Doopliss/main.py", line 60, in <module>
    bot.run(TOKEN)
  File "/usr/local/lib/python3.10/dist-packages/discord/client.py", line 717, in run
    return future.result()
  File "/usr/local/lib/python3.10/dist-packages/discord/client.py", line 696, in runner
    await self.start(*args, **kwargs)
  File "/usr/local/lib/python3.10/dist-packages/discord/client.py", line 659, in start
    await self.login(token)
  File "/usr/local/lib/python3.10/dist-packages/discord/client.py", line 514, in login
    data = await self.http.static_login(token.strip())
  File "/usr/local/lib/python3.10/dist-packages/discord/http.py", line 410, in static_login
    raise LoginFailure("Improper token has been passed.") from exc
discord.errors.LoginFailure: Improper token has been passed.
Traceback (most recent call last):
  File "/usr/local/lib/python3.10/dist-packages/discord/http.py", line 406, in static_login
    data = await self.request(Route("GET", "/users/@me"))
  File "/usr/local/lib/python3.10/dist-packages/discord/http.py", line 359, in request
    raise HTTPException(response, data)
discord.errors.HTTPException: 401 Unauthorized (error code: 0): 401: Unauthorized

The above exception was the direct cause of the following exception:

Traceback (most recent call last):
  File "/root/Doopliss/main.py", line 60, in <module>
    bot.run(TOKEN)
  File "/usr/local/lib/python3.10/dist-packages/discord/client.py", line 717, in run
    return future.result()
  File "/usr/local/lib/python3.10/dist-packages/discord/client.py", line 696, in runner
    await self.start(*args, **kwargs)
  File "/usr/local/lib/python3.10/dist-packages/discord/client.py", line 659, in start
    await self.login(token)
  File "/usr/local/lib/python3.10/dist-packages/discord/client.py", line 514, in login
    data = await self.http.static_login(token.strip())
  File "/usr/local/lib/python3.10/dist-packages/discord/http.py", line 410, in static_login
    raise LoginFailure("Improper token has been passed.") from exc
discord.errors.LoginFailure: Improper token has been passed.
Traceback (most recent call last):
  File "/usr/local/lib/python3.10/dist-packages/discord/http.py", line 406, in static_login
    data = await self.request(Route("GET", "/users/@me"))
  File "/usr/local/lib/python3.10/dist-packages/discord/http.py", line 359, in request
    raise HTTPException(response, data)
discord.errors.HTTPException: 401 Unauthorized (error code: 0): 401: Unauthorized

The above exception was the direct cause of the following exception:

Traceback (most recent call last):
  File "/root/Doopliss/main.py", line 60, in <module>
    bot.run(TOKEN)
  File "/usr/local/lib/python3.10/dist-packages/discord/client.py", line 717, in run
    return future.result()
  File "/usr/local/lib/python3.10/dist-packages/discord/client.py", line 696, in runner
    await self.start(*args, **kwargs)
  File "/usr/local/lib/python3.10/dist-packages/discord/client.py", line 659, in start
    await self.login(token)
  File "/usr/local/lib/python3.10/dist-packages/discord/client.py", line 514, in login
    data = await self.http.static_login(token.strip())
  File "/usr/local/lib/python3.10/dist-packages/discord/http.py", line 410, in static_login
    raise LoginFailure("Improper token has been passed.") from exc
discord.errors.LoginFailure: Improper token has been passed.
Traceback (most recent call last):
  File "/usr/local/lib/python3.10/dist-packages/discord/http.py", line 406, in static_login
    data = await self.request(Route("GET", "/users/@me"))
  File "/usr/local/lib/python3.10/dist-packages/discord/http.py", line 359, in request
    raise HTTPException(response, data)
discord.errors.HTTPException: 401 Unauthorized (error code: 0): 401: Unauthorized

The above exception was the direct cause of the following exception:

Traceback (most recent call last):
  File "/root/Doopliss/main.py", line 60, in <module>
    bot.run(TOKEN)
  File "/usr/local/lib/python3.10/dist-packages/discord/client.py", line 717, in run
    return future.result()
  File "/usr/local/lib/python3.10/dist-packages/discord/client.py", line 696, in runner
    await self.start(*args, **kwargs)
  File "/usr/local/lib/python3.10/dist-packages/discord/client.py", line 659, in start
    await self.login(token)
  File "/usr/local/lib/python3.10/dist-packages/discord/client.py", line 514, in login
    data = await self.http.static_login(token.strip())
  File "/usr/local/lib/python3.10/dist-packages/discord/http.py", line 410, in static_login
    raise LoginFailure("Improper token has been passed.") from exc
discord.errors.LoginFailure: Improper token has been passed.
Traceback (most recent call last):
  File "/usr/local/lib/python3.10/dist-packages/discord/http.py", line 406, in static_login
    data = await self.request(Route("GET", "/users/@me"))
  File "/usr/local/lib/python3.10/dist-packages/discord/http.py", line 359, in request
    raise HTTPException(response, data)
discord.errors.HTTPException: 401 Unauthorized (error code: 0): 401: Unauthorized

The above exception was the direct cause of the following exception:

Traceback (most recent call last):
  File "/root/Doopliss/main.py", line 60, in <module>
    bot.run(TOKEN)
  File "/usr/local/lib/python3.10/dist-packages/discord/client.py", line 717, in run
    return future.result()
  File "/usr/local/lib/python3.10/dist-packages/discord/client.py", line 696, in runner
    await self.start(*args, **kwargs)
  File "/usr/local/lib/python3.10/dist-packages/discord/client.py", line 659, in start
    await self.login(token)
  File "/usr/local/lib/python3.10/dist-packages/discord/client.py", line 514, in login
    data = await self.http.static_login(token.strip())
  File "/usr/local/lib/python3.10/dist-packages/discord/http.py", line 410, in static_login
    raise LoginFailure("Improper token has been passed.") from exc
discord.errors.LoginFailure: Improper token has been passed.
/usr/lib/python3/dist-packages/requests/__init__.py:87: RequestsDependencyWarning: urllib3 (2.0.3) or chardet (4.0.0) doesn't match a supported version!
  warnings.warn("urllib3 ({}) or chardet ({}) doesn't match a supported "
Traceback (most recent call last):
  File "/usr/local/lib/python3.10/dist-packages/discord/http.py", line 406, in static_login
    data = await self.request(Route("GET", "/users/@me"))
  File "/usr/local/lib/python3.10/dist-packages/discord/http.py", line 359, in request
    raise HTTPException(response, data)
discord.errors.HTTPException: 401 Unauthorized (error code: 0): 401: Unauthorized

The above exception was the direct cause of the following exception:

Traceback (most recent call last):
  File "/root/Doopliss/main.py", line 60, in <module>
    bot.run(TOKEN)
  File "/usr/local/lib/python3.10/dist-packages/discord/client.py", line 717, in run
    return future.result()
  File "/usr/local/lib/python3.10/dist-packages/discord/client.py", line 696, in runner
    await self.start(*args, **kwargs)
  File "/usr/local/lib/python3.10/dist-packages/discord/client.py", line 659, in start
    await self.login(token)
  File "/usr/local/lib/python3.10/dist-packages/discord/client.py", line 514, in login
    data = await self.http.static_login(token.strip())
  File "/usr/local/lib/python3.10/dist-packages/discord/http.py", line 410, in static_login
    raise LoginFailure("Improper token has been passed.") from exc
discord.errors.LoginFailure: Improper token has been passed.
/usr/lib/python3/dist-packages/requests/__init__.py:87: RequestsDependencyWarning: urllib3 (2.0.3) or chardet (4.0.0) doesn't match a supported version!
  warnings.warn("urllib3 ({}) or chardet ({}) doesn't match a supported "
Traceback (most recent call last):
  File "/usr/local/lib/python3.10/dist-packages/discord/http.py", line 406, in static_login
    data = await self.request(Route("GET", "/users/@me"))
  File "/usr/local/lib/python3.10/dist-packages/discord/http.py", line 359, in request
    raise HTTPException(response, data)
discord.errors.HTTPException: 401 Unauthorized (error code: 0): 401: Unauthorized

The above exception was the direct cause of the following exception:

Traceback (most recent call last):
  File "/root/Doopliss/main.py", line 60, in <module>
    bot.run(TOKEN)
  File "/usr/local/lib/python3.10/dist-packages/discord/client.py", line 717, in run
    return future.result()
  File "/usr/local/lib/python3.10/dist-packages/discord/client.py", line 696, in runner
    await self.start(*args, **kwargs)
  File "/usr/local/lib/python3.10/dist-packages/discord/client.py", line 659, in start
    await self.login(token)
  File "/usr/local/lib/python3.10/dist-packages/discord/client.py", line 514, in login
    data = await self.http.static_login(token.strip())
  File "/usr/local/lib/python3.10/dist-packages/discord/http.py", line 410, in static_login
    raise LoginFailure("Improper token has been passed.") from exc
discord.errors.LoginFailure: Improper token has been passed.
/usr/lib/python3/dist-packages/requests/__init__.py:87: RequestsDependencyWarning: urllib3 (2.0.3) or chardet (4.0.0) doesn't match a supported version!
  warnings.warn("urllib3 ({}) or chardet ({}) doesn't match a supported "
Traceback (most recent call last):
  File "/usr/local/lib/python3.10/dist-packages/discord/http.py", line 406, in static_login
    data = await self.request(Route("GET", "/users/@me"))
  File "/usr/local/lib/python3.10/dist-packages/discord/http.py", line 359, in request
    raise HTTPException(response, data)
discord.errors.HTTPException: 401 Unauthorized (error code: 0): 401: Unauthorized

The above exception was the direct cause of the following exception:

Traceback (most recent call last):
  File "/root/Doopliss/main.py", line 60, in <module>
    bot.run(TOKEN)
  File "/usr/local/lib/python3.10/dist-packages/discord/client.py", line 717, in run
    return future.result()
  File "/usr/local/lib/python3.10/dist-packages/discord/client.py", line 696, in runner
    await self.start(*args, **kwargs)
  File "/usr/local/lib/python3.10/dist-packages/discord/client.py", line 659, in start
    await self.login(token)
  File "/usr/local/lib/python3.10/dist-packages/discord/client.py", line 514, in login
    data = await self.http.static_login(token.strip())
  File "/usr/local/lib/python3.10/dist-packages/discord/http.py", line 410, in static_login
    raise LoginFailure("Improper token has been passed.") from exc
discord.errors.LoginFailure: Improper token has been passed.
/usr/lib/python3/dist-packages/requests/__init__.py:87: RequestsDependencyWarning: urllib3 (2.0.3) or chardet (4.0.0) doesn't match a supported version!
  warnings.warn("urllib3 ({}) or chardet ({}) doesn't match a supported "
Traceback (most recent call last):
  File "/usr/local/lib/python3.10/dist-packages/discord/http.py", line 406, in static_login
    data = await self.request(Route("GET", "/users/@me"))
  File "/usr/local/lib/python3.10/dist-packages/discord/http.py", line 359, in request
    raise HTTPException(response, data)
discord.errors.HTTPException: 401 Unauthorized (error code: 0): 401: Unauthorized

The above exception was the direct cause of the following exception:

Traceback (most recent call last):
  File "/root/Doopliss/main.py", line 60, in <module>
    bot.run(TOKEN)
  File "/usr/local/lib/python3.10/dist-packages/discord/client.py", line 717, in run
    return future.result()
  File "/usr/local/lib/python3.10/dist-packages/discord/client.py", line 696, in runner
    await self.start(*args, **kwargs)
  File "/usr/local/lib/python3.10/dist-packages/discord/client.py", line 659, in start
    await self.login(token)
  File "/usr/local/lib/python3.10/dist-packages/discord/client.py", line 514, in login
    data = await self.http.static_login(token.strip())
  File "/usr/local/lib/python3.10/dist-packages/discord/http.py", line 410, in static_login
    raise LoginFailure("Improper token has been passed.") from exc
discord.errors.LoginFailure: Improper token has been passed.
/usr/lib/python3/dist-packages/requests/__init__.py:87: RequestsDependencyWarning: urllib3 (2.0.3) or chardet (4.0.0) doesn't match a supported version!
  warnings.warn("urllib3 ({}) or chardet ({}) doesn't match a supported "
Traceback (most recent call last):
  File "/usr/local/lib/python3.10/dist-packages/discord/http.py", line 406, in static_login
    data = await self.request(Route("GET", "/users/@me"))
  File "/usr/local/lib/python3.10/dist-packages/discord/http.py", line 359, in request
    raise HTTPException(response, data)
discord.errors.HTTPException: 401 Unauthorized (error code: 0): 401: Unauthorized

The above exception was the direct cause of the following exception:

Traceback (most recent call last):
  File "/root/Doopliss/main.py", line 60, in <module>
    bot.run(TOKEN)
  File "/usr/local/lib/python3.10/dist-packages/discord/client.py", line 717, in run
    return future.result()
  File "/usr/local/lib/python3.10/dist-packages/discord/client.py", line 696, in runner
    await self.start(*args, **kwargs)
  File "/usr/local/lib/python3.10/dist-packages/discord/client.py", line 659, in start
    await self.login(token)
  File "/usr/local/lib/python3.10/dist-packages/discord/client.py", line 514, in login
    data = await self.http.static_login(token.strip())
  File "/usr/local/lib/python3.10/dist-packages/discord/http.py", line 410, in static_login
    raise LoginFailure("Improper token has been passed.") from exc
discord.errors.LoginFailure: Improper token has been passed.
/usr/lib/python3/dist-packages/requests/__init__.py:87: RequestsDependencyWarning: urllib3 (2.0.3) or chardet (4.0.0) doesn't match a supported version!
  warnings.warn("urllib3 ({}) or chardet ({}) doesn't match a supported "
Traceback (most recent call last):
  File "/usr/local/lib/python3.10/dist-packages/discord/http.py", line 406, in static_login
    data = await self.request(Route("GET", "/users/@me"))
  File "/usr/local/lib/python3.10/dist-packages/discord/http.py", line 359, in request
    raise HTTPException(response, data)
discord.errors.HTTPException: 401 Unauthorized (error code: 0): 401: Unauthorized

The above exception was the direct cause of the following exception:

Traceback (most recent call last):
  File "/root/Doopliss/main.py", line 60, in <module>
    bot.run(TOKEN)
  File "/usr/local/lib/python3.10/dist-packages/discord/client.py", line 717, in run
    return future.result()
  File "/usr/local/lib/python3.10/dist-packages/discord/client.py", line 696, in runner
    await self.start(*args, **kwargs)
  File "/usr/local/lib/python3.10/dist-packages/discord/client.py", line 659, in start
    await self.login(token)
  File "/usr/local/lib/python3.10/dist-packages/discord/client.py", line 514, in login
    data = await self.http.static_login(token.strip())
  File "/usr/local/lib/python3.10/dist-packages/discord/http.py", line 410, in static_login
    raise LoginFailure("Improper token has been passed.") from exc
discord.errors.LoginFailure: Improper token has been passed.
/usr/lib/python3/dist-packages/requests/__init__.py:87: RequestsDependencyWarning: urllib3 (2.0.3) or chardet (4.0.0) doesn't match a supported version!
  warnings.warn("urllib3 ({}) or chardet ({}) doesn't match a supported "
Traceback (most recent call last):
  File "/usr/local/lib/python3.10/dist-packages/discord/http.py", line 406, in static_login
    data = await self.request(Route("GET", "/users/@me"))
  File "/usr/local/lib/python3.10/dist-packages/discord/http.py", line 359, in request
    raise HTTPException(response, data)
discord.errors.HTTPException: 401 Unauthorized (error code: 0): 401: Unauthorized

The above exception was the direct cause of the following exception:

Traceback (most recent call last):
  File "/root/Doopliss/main.py", line 60, in <module>
    bot.run(TOKEN)
  File "/usr/local/lib/python3.10/dist-packages/discord/client.py", line 717, in run
    return future.result()
  File "/usr/local/lib/python3.10/dist-packages/discord/client.py", line 696, in runner
    await self.start(*args, **kwargs)
  File "/usr/local/lib/python3.10/dist-packages/discord/client.py", line 659, in start
    await self.login(token)
  File "/usr/local/lib/python3.10/dist-packages/discord/client.py", line 514, in login
    data = await self.http.static_login(token.strip())
  File "/usr/local/lib/python3.10/dist-packages/discord/http.py", line 410, in static_login
    raise LoginFailure("Improper token has been passed.") from exc
discord.errors.LoginFailure: Improper token has been passed.
/usr/lib/python3/dist-packages/requests/__init__.py:87: RequestsDependencyWarning: urllib3 (2.0.3) or chardet (4.0.0) doesn't match a supported version!
  warnings.warn("urllib3 ({}) or chardet ({}) doesn't match a supported "
Traceback (most recent call last):
  File "/usr/local/lib/python3.10/dist-packages/discord/http.py", line 406, in static_login
    data = await self.request(Route("GET", "/users/@me"))
  File "/usr/local/lib/python3.10/dist-packages/discord/http.py", line 359, in request
    raise HTTPException(response, data)
discord.errors.HTTPException: 401 Unauthorized (error code: 0): 401: Unauthorized

The above exception was the direct cause of the following exception:

Traceback (most recent call last):
  File "/root/Doopliss/main.py", line 60, in <module>
    bot.run(TOKEN)
  File "/usr/local/lib/python3.10/dist-packages/discord/client.py", line 717, in run
    return future.result()
  File "/usr/local/lib/python3.10/dist-packages/discord/client.py", line 696, in runner
    await self.start(*args, **kwargs)
  File "/usr/local/lib/python3.10/dist-packages/discord/client.py", line 659, in start
    await self.login(token)
  File "/usr/local/lib/python3.10/dist-packages/discord/client.py", line 514, in login
    data = await self.http.static_login(token.strip())
  File "/usr/local/lib/python3.10/dist-packages/discord/http.py", line 410, in static_login
    raise LoginFailure("Improper token has been passed.") from exc
discord.errors.LoginFailure: Improper token has been passed.
/usr/lib/python3/dist-packages/requests/__init__.py:87: RequestsDependencyWarning: urllib3 (2.0.3) or chardet (4.0.0) doesn't match a supported version!
  warnings.warn("urllib3 ({}) or chardet ({}) doesn't match a supported "
Traceback (most recent call last):
  File "/usr/local/lib/python3.10/dist-packages/discord/http.py", line 406, in static_login
    data = await self.request(Route("GET", "/users/@me"))
  File "/usr/local/lib/python3.10/dist-packages/discord/http.py", line 359, in request
    raise HTTPException(response, data)
discord.errors.HTTPException: 401 Unauthorized (error code: 0): 401: Unauthorized

The above exception was the direct cause of the following exception:

Traceback (most recent call last):
  File "/root/Doopliss/main.py", line 60, in <module>
    bot.run(TOKEN)
  File "/usr/local/lib/python3.10/dist-packages/discord/client.py", line 717, in run
    return future.result()
  File "/usr/local/lib/python3.10/dist-packages/discord/client.py", line 696, in runner
    await self.start(*args, **kwargs)
  File "/usr/local/lib/python3.10/dist-packages/discord/client.py", line 659, in start
    await self.login(token)
  File "/usr/local/lib/python3.10/dist-packages/discord/client.py", line 514, in login
    data = await self.http.static_login(token.strip())
  File "/usr/local/lib/python3.10/dist-packages/discord/http.py", line 410, in static_login
    raise LoginFailure("Improper token has been passed.") from exc
discord.errors.LoginFailure: Improper token has been passed.
/usr/lib/python3/dist-packages/requests/__init__.py:87: RequestsDependencyWarning: urllib3 (2.0.3) or chardet (4.0.0) doesn't match a supported version!
  warnings.warn("urllib3 ({}) or chardet ({}) doesn't match a supported "
Traceback (most recent call last):
  File "/usr/local/lib/python3.10/dist-packages/discord/http.py", line 406, in static_login
    data = await self.request(Route("GET", "/users/@me"))
  File "/usr/local/lib/python3.10/dist-packages/discord/http.py", line 359, in request
    raise HTTPException(response, data)
discord.errors.HTTPException: 401 Unauthorized (error code: 0): 401: Unauthorized

The above exception was the direct cause of the following exception:

Traceback (most recent call last):
  File "/root/Doopliss/main.py", line 60, in <module>
    bot.run(TOKEN)
  File "/usr/local/lib/python3.10/dist-packages/discord/client.py", line 717, in run
    return future.result()
  File "/usr/local/lib/python3.10/dist-packages/discord/client.py", line 696, in runner
    await self.start(*args, **kwargs)
  File "/usr/local/lib/python3.10/dist-packages/discord/client.py", line 659, in start
    await self.login(token)
  File "/usr/local/lib/python3.10/dist-packages/discord/client.py", line 514, in login
    data = await self.http.static_login(token.strip())
  File "/usr/local/lib/python3.10/dist-packages/discord/http.py", line 410, in static_login
    raise LoginFailure("Improper token has been passed.") from exc
discord.errors.LoginFailure: Improper token has been passed.
/usr/lib/python3/dist-packages/requests/__init__.py:87: RequestsDependencyWarning: urllib3 (2.0.3) or chardet (4.0.0) doesn't match a supported version!
  warnings.warn("urllib3 ({}) or chardet ({}) doesn't match a supported "
Traceback (most recent call last):
  File "/usr/local/lib/python3.10/dist-packages/discord/http.py", line 406, in static_login
    data = await self.request(Route("GET", "/users/@me"))
  File "/usr/local/lib/python3.10/dist-packages/discord/http.py", line 359, in request
    raise HTTPException(response, data)
discord.errors.HTTPException: 401 Unauthorized (error code: 0): 401: Unauthorized

The above exception was the direct cause of the following exception:

Traceback (most recent call last):
  File "/root/Doopliss/main.py", line 60, in <module>
    bot.run(TOKEN)
  File "/usr/local/lib/python3.10/dist-packages/discord/client.py", line 717, in run
    return future.result()
  File "/usr/local/lib/python3.10/dist-packages/discord/client.py", line 696, in runner
    await self.start(*args, **kwargs)
  File "/usr/local/lib/python3.10/dist-packages/discord/client.py", line 659, in start
    await self.login(token)
  File "/usr/local/lib/python3.10/dist-packages/discord/client.py", line 514, in login
    data = await self.http.static_login(token.strip())
  File "/usr/local/lib/python3.10/dist-packages/discord/http.py", line 410, in static_login
    raise LoginFailure("Improper token has been passed.") from exc
discord.errors.LoginFailure: Improper token has been passed.
/usr/lib/python3/dist-packages/requests/__init__.py:87: RequestsDependencyWarning: urllib3 (2.0.3) or chardet (4.0.0) doesn't match a supported version!
  warnings.warn("urllib3 ({}) or chardet ({}) doesn't match a supported "
Traceback (most recent call last):
  File "/usr/local/lib/python3.10/dist-packages/discord/http.py", line 406, in static_login
    data = await self.request(Route("GET", "/users/@me"))
  File "/usr/local/lib/python3.10/dist-packages/discord/http.py", line 359, in request
    raise HTTPException(response, data)
discord.errors.HTTPException: 401 Unauthorized (error code: 0): 401: Unauthorized

The above exception was the direct cause of the following exception:

Traceback (most recent call last):
  File "/root/Doopliss/main.py", line 60, in <module>
    bot.run(TOKEN)
  File "/usr/local/lib/python3.10/dist-packages/discord/client.py", line 717, in run
    return future.result()
  File "/usr/local/lib/python3.10/dist-packages/discord/client.py", line 696, in runner
    await self.start(*args, **kwargs)
  File "/usr/local/lib/python3.10/dist-packages/discord/client.py", line 659, in start
    await self.login(token)
  File "/usr/local/lib/python3.10/dist-packages/discord/client.py", line 514, in login
    data = await self.http.static_login(token.strip())
  File "/usr/local/lib/python3.10/dist-packages/discord/http.py", line 410, in static_login
    raise LoginFailure("Improper token has been passed.") from exc
discord.errors.LoginFailure: Improper token has been passed.
/usr/lib/python3/dist-packages/requests/__init__.py:87: RequestsDependencyWarning: urllib3 (2.0.3) or chardet (4.0.0) doesn't match a supported version!
  warnings.warn("urllib3 ({}) or chardet ({}) doesn't match a supported "
Traceback (most recent call last):
  File "/usr/local/lib/python3.10/dist-packages/discord/http.py", line 406, in static_login
    data = await self.request(Route("GET", "/users/@me"))
  File "/usr/local/lib/python3.10/dist-packages/discord/http.py", line 359, in request
    raise HTTPException(response, data)
discord.errors.HTTPException: 401 Unauthorized (error code: 0): 401: Unauthorized

The above exception was the direct cause of the following exception:

Traceback (most recent call last):
  File "/root/Doopliss/main.py", line 60, in <module>
    bot.run(TOKEN)
  File "/usr/local/lib/python3.10/dist-packages/discord/client.py", line 717, in run
    return future.result()
  File "/usr/local/lib/python3.10/dist-packages/discord/client.py", line 696, in runner
    await self.start(*args, **kwargs)
  File "/usr/local/lib/python3.10/dist-packages/discord/client.py", line 659, in start
    await self.login(token)
  File "/usr/local/lib/python3.10/dist-packages/discord/client.py", line 514, in login
    data = await self.http.static_login(token.strip())
  File "/usr/local/lib/python3.10/dist-packages/discord/http.py", line 410, in static_login
    raise LoginFailure("Improper token has been passed.") from exc
discord.errors.LoginFailure: Improper token has been passed.
/usr/lib/python3/dist-packages/requests/__init__.py:87: RequestsDependencyWarning: urllib3 (2.0.3) or chardet (4.0.0) doesn't match a supported version!
  warnings.warn("urllib3 ({}) or chardet ({}) doesn't match a supported "
Traceback (most recent call last):
  File "/usr/local/lib/python3.10/dist-packages/discord/http.py", line 406, in static_login
    data = await self.request(Route("GET", "/users/@me"))
  File "/usr/local/lib/python3.10/dist-packages/discord/http.py", line 359, in request
    raise HTTPException(response, data)
discord.errors.HTTPException: 401 Unauthorized (error code: 0): 401: Unauthorized

The above exception was the direct cause of the following exception:

Traceback (most recent call last):
  File "/root/Doopliss/main.py", line 60, in <module>
    bot.run(TOKEN)
  File "/usr/local/lib/python3.10/dist-packages/discord/client.py", line 717, in run
    return future.result()
  File "/usr/local/lib/python3.10/dist-packages/discord/client.py", line 696, in runner
    await self.start(*args, **kwargs)
  File "/usr/local/lib/python3.10/dist-packages/discord/client.py", line 659, in start
    await self.login(token)
  File "/usr/local/lib/python3.10/dist-packages/discord/client.py", line 514, in login
    data = await self.http.static_login(token.strip())
  File "/usr/local/lib/python3.10/dist-packages/discord/http.py", line 410, in static_login
    raise LoginFailure("Improper token has been passed.") from exc
discord.errors.LoginFailure: Improper token has been passed.
/usr/lib/python3/dist-packages/requests/__init__.py:87: RequestsDependencyWarning: urllib3 (2.0.3) or chardet (4.0.0) doesn't match a supported version!
  warnings.warn("urllib3 ({}) or chardet ({}) doesn't match a supported "
Traceback (most recent call last):
  File "/usr/local/lib/python3.10/dist-packages/discord/http.py", line 406, in static_login
    data = await self.request(Route("GET", "/users/@me"))
  File "/usr/local/lib/python3.10/dist-packages/discord/http.py", line 359, in request
    raise HTTPException(response, data)
discord.errors.HTTPException: 401 Unauthorized (error code: 0): 401: Unauthorized

The above exception was the direct cause of the following exception:

Traceback (most recent call last):
  File "/root/Doopliss/main.py", line 60, in <module>
    bot.run(TOKEN)
  File "/usr/local/lib/python3.10/dist-packages/discord/client.py", line 717, in run
    return future.result()
  File "/usr/local/lib/python3.10/dist-packages/discord/client.py", line 696, in runner
    await self.start(*args, **kwargs)
  File "/usr/local/lib/python3.10/dist-packages/discord/client.py", line 659, in start
    await self.login(token)
  File "/usr/local/lib/python3.10/dist-packages/discord/client.py", line 514, in login
    data = await self.http.static_login(token.strip())
  File "/usr/local/lib/python3.10/dist-packages/discord/http.py", line 410, in static_login
    raise LoginFailure("Improper token has been passed.") from exc
discord.errors.LoginFailure: Improper token has been passed.
/usr/lib/python3/dist-packages/requests/__init__.py:87: RequestsDependencyWarning: urllib3 (2.0.3) or chardet (4.0.0) doesn't match a supported version!
  warnings.warn("urllib3 ({}) or chardet ({}) doesn't match a supported "
/usr/lib/python3/dist-packages/requests/__init__.py:87: RequestsDependencyWarning: urllib3 (2.0.3) or chardet (4.0.0) doesn't match a supported version!
  warnings.warn("urllib3 ({}) or chardet ({}) doesn't match a supported "
Traceback (most recent call last):
  File "/usr/local/lib/python3.10/dist-packages/discord/http.py", line 406, in static_login
    data = await self.request(Route("GET", "/users/@me"))
  File "/usr/local/lib/python3.10/dist-packages/discord/http.py", line 359, in request
    raise HTTPException(response, data)
discord.errors.HTTPException: 401 Unauthorized (error code: 0): 401: Unauthorized

The above exception was the direct cause of the following exception:

Traceback (most recent call last):
  File "/root/Doopliss/main.py", line 60, in <module>
    bot.run(TOKEN)
  File "/usr/local/lib/python3.10/dist-packages/discord/client.py", line 717, in run
    return future.result()
  File "/usr/local/lib/python3.10/dist-packages/discord/client.py", line 696, in runner
    await self.start(*args, **kwargs)
  File "/usr/local/lib/python3.10/dist-packages/discord/client.py", line 659, in start
    await self.login(token)
  File "/usr/local/lib/python3.10/dist-packages/discord/client.py", line 514, in login
    data = await self.http.static_login(token.strip())
  File "/usr/local/lib/python3.10/dist-packages/discord/http.py", line 410, in static_login
    raise LoginFailure("Improper token has been passed.") from exc
discord.errors.LoginFailure: Improper token has been passed.
/usr/lib/python3/dist-packages/requests/__init__.py:87: RequestsDependencyWarning: urllib3 (2.0.3) or chardet (4.0.0) doesn't match a supported version!
  warnings.warn("urllib3 ({}) or chardet ({}) doesn't match a supported "
Traceback (most recent call last):
  File "/usr/local/lib/python3.10/dist-packages/discord/http.py", line 406, in static_login
    data = await self.request(Route("GET", "/users/@me"))
  File "/usr/local/lib/python3.10/dist-packages/discord/http.py", line 359, in request
    raise HTTPException(response, data)
discord.errors.HTTPException: 401 Unauthorized (error code: 0): 401: Unauthorized

The above exception was the direct cause of the following exception:

Traceback (most recent call last):
  File "/root/Doopliss/main.py", line 60, in <module>
    bot.run(TOKEN)
  File "/usr/local/lib/python3.10/dist-packages/discord/client.py", line 717, in run
    return future.result()
  File "/usr/local/lib/python3.10/dist-packages/discord/client.py", line 696, in runner
    await self.start(*args, **kwargs)
  File "/usr/local/lib/python3.10/dist-packages/discord/client.py", line 659, in start
    await self.login(token)
  File "/usr/local/lib/python3.10/dist-packages/discord/client.py", line 514, in login
    data = await self.http.static_login(token.strip())
  File "/usr/local/lib/python3.10/dist-packages/discord/http.py", line 410, in static_login
    raise LoginFailure("Improper token has been passed.") from exc
discord.errors.LoginFailure: Improper token has been passed.
/usr/lib/python3/dist-packages/requests/__init__.py:87: RequestsDependencyWarning: urllib3 (2.0.3) or chardet (4.0.0) doesn't match a supported version!
  warnings.warn("urllib3 ({}) or chardet ({}) doesn't match a supported "
Traceback (most recent call last):
  File "/usr/local/lib/python3.10/dist-packages/discord/http.py", line 406, in static_login
    data = await self.request(Route("GET", "/users/@me"))
  File "/usr/local/lib/python3.10/dist-packages/discord/http.py", line 359, in request
    raise HTTPException(response, data)
discord.errors.HTTPException: 401 Unauthorized (error code: 0): 401: Unauthorized

The above exception was the direct cause of the following exception:

Traceback (most recent call last):
  File "/root/Doopliss/main.py", line 60, in <module>
    bot.run(TOKEN)
  File "/usr/local/lib/python3.10/dist-packages/discord/client.py", line 717, in run
    return future.result()
  File "/usr/local/lib/python3.10/dist-packages/discord/client.py", line 696, in runner
    await self.start(*args, **kwargs)
  File "/usr/local/lib/python3.10/dist-packages/discord/client.py", line 659, in start
    await self.login(token)
  File "/usr/local/lib/python3.10/dist-packages/discord/client.py", line 514, in login
    data = await self.http.static_login(token.strip())
  File "/usr/local/lib/python3.10/dist-packages/discord/http.py", line 410, in static_login
    raise LoginFailure("Improper token has been passed.") from exc
discord.errors.LoginFailure: Improper token has been passed.
/usr/lib/python3/dist-packages/requests/__init__.py:87: RequestsDependencyWarning: urllib3 (2.0.3) or chardet (4.0.0) doesn't match a supported version!
  warnings.warn("urllib3 ({}) or chardet ({}) doesn't match a supported "
Traceback (most recent call last):
  File "/usr/local/lib/python3.10/dist-packages/discord/http.py", line 406, in static_login
    data = await self.request(Route("GET", "/users/@me"))
  File "/usr/local/lib/python3.10/dist-packages/discord/http.py", line 359, in request
    raise HTTPException(response, data)
discord.errors.HTTPException: 401 Unauthorized (error code: 0): 401: Unauthorized

The above exception was the direct cause of the following exception:

Traceback (most recent call last):
  File "/root/Doopliss/main.py", line 60, in <module>
    bot.run(TOKEN)
  File "/usr/local/lib/python3.10/dist-packages/discord/client.py", line 717, in run
    return future.result()
  File "/usr/local/lib/python3.10/dist-packages/discord/client.py", line 696, in runner
    await self.start(*args, **kwargs)
  File "/usr/local/lib/python3.10/dist-packages/discord/client.py", line 659, in start
    await self.login(token)
  File "/usr/local/lib/python3.10/dist-packages/discord/client.py", line 514, in login
    data = await self.http.static_login(token.strip())
  File "/usr/local/lib/python3.10/dist-packages/discord/http.py", line 410, in static_login
    raise LoginFailure("Improper token has been passed.") from exc
discord.errors.LoginFailure: Improper token has been passed.
/usr/lib/python3/dist-packages/requests/__init__.py:87: RequestsDependencyWarning: urllib3 (2.0.3) or chardet (4.0.0) doesn't match a supported version!
  warnings.warn("urllib3 ({}) or chardet ({}) doesn't match a supported "
Traceback (most recent call last):
  File "/usr/local/lib/python3.10/dist-packages/discord/http.py", line 406, in static_login
    data = await self.request(Route("GET", "/users/@me"))
  File "/usr/local/lib/python3.10/dist-packages/discord/http.py", line 359, in request
    raise HTTPException(response, data)
discord.errors.HTTPException: 401 Unauthorized (error code: 0): 401: Unauthorized

The above exception was the direct cause of the following exception:

Traceback (most recent call last):
  File "/root/Doopliss/main.py", line 60, in <module>
    bot.run(TOKEN)
  File "/usr/local/lib/python3.10/dist-packages/discord/client.py", line 717, in run
    return future.result()
  File "/usr/local/lib/python3.10/dist-packages/discord/client.py", line 696, in runner
    await self.start(*args, **kwargs)
  File "/usr/local/lib/python3.10/dist-packages/discord/client.py", line 659, in start
    await self.login(token)
  File "/usr/local/lib/python3.10/dist-packages/discord/client.py", line 514, in login
    data = await self.http.static_login(token.strip())
  File "/usr/local/lib/python3.10/dist-packages/discord/http.py", line 410, in static_login
    raise LoginFailure("Improper token has been passed.") from exc
discord.errors.LoginFailure: Improper token has been passed.
/usr/lib/python3/dist-packages/requests/__init__.py:87: RequestsDependencyWarning: urllib3 (2.0.3) or chardet (4.0.0) doesn't match a supported version!
  warnings.warn("urllib3 ({}) or chardet ({}) doesn't match a supported "
Traceback (most recent call last):
  File "/usr/local/lib/python3.10/dist-packages/discord/http.py", line 406, in static_login
    data = await self.request(Route("GET", "/users/@me"))
  File "/usr/local/lib/python3.10/dist-packages/discord/http.py", line 359, in request
    raise HTTPException(response, data)
discord.errors.HTTPException: 401 Unauthorized (error code: 0): 401: Unauthorized

The above exception was the direct cause of the following exception:

Traceback (most recent call last):
  File "/root/Doopliss/main.py", line 60, in <module>
    bot.run(TOKEN)
  File "/usr/local/lib/python3.10/dist-packages/discord/client.py", line 717, in run
    return future.result()
  File "/usr/local/lib/python3.10/dist-packages/discord/client.py", line 696, in runner
    await self.start(*args, **kwargs)
  File "/usr/local/lib/python3.10/dist-packages/discord/client.py", line 659, in start
    await self.login(token)
  File "/usr/local/lib/python3.10/dist-packages/discord/client.py", line 514, in login
    data = await self.http.static_login(token.strip())
  File "/usr/local/lib/python3.10/dist-packages/discord/http.py", line 410, in static_login
    raise LoginFailure("Improper token has been passed.") from exc
discord.errors.LoginFailure: Improper token has been passed.
/usr/lib/python3/dist-packages/requests/__init__.py:87: RequestsDependencyWarning: urllib3 (2.0.3) or chardet (4.0.0) doesn't match a supported version!
  warnings.warn("urllib3 ({}) or chardet ({}) doesn't match a supported "
Traceback (most recent call last):
  File "/usr/local/lib/python3.10/dist-packages/discord/http.py", line 406, in static_login
    data = await self.request(Route("GET", "/users/@me"))
  File "/usr/local/lib/python3.10/dist-packages/discord/http.py", line 359, in request
    raise HTTPException(response, data)
discord.errors.HTTPException: 401 Unauthorized (error code: 0): 401: Unauthorized

The above exception was the direct cause of the following exception:

Traceback (most recent call last):
  File "/root/Doopliss/main.py", line 60, in <module>
    bot.run(TOKEN)
  File "/usr/local/lib/python3.10/dist-packages/discord/client.py", line 717, in run
    return future.result()
  File "/usr/local/lib/python3.10/dist-packages/discord/client.py", line 696, in runner
    await self.start(*args, **kwargs)
  File "/usr/local/lib/python3.10/dist-packages/discord/client.py", line 659, in start
    await self.login(token)
  File "/usr/local/lib/python3.10/dist-packages/discord/client.py", line 514, in login
    data = await self.http.static_login(token.strip())
  File "/usr/local/lib/python3.10/dist-packages/discord/http.py", line 410, in static_login
    raise LoginFailure("Improper token has been passed.") from exc
discord.errors.LoginFailure: Improper token has been passed.
/usr/lib/python3/dist-packages/requests/__init__.py:87: RequestsDependencyWarning: urllib3 (2.0.3) or chardet (4.0.0) doesn't match a supported version!
  warnings.warn("urllib3 ({}) or chardet ({}) doesn't match a supported "
Traceback (most recent call last):
  File "/usr/local/lib/python3.10/dist-packages/discord/http.py", line 406, in static_login
    data = await self.request(Route("GET", "/users/@me"))
  File "/usr/local/lib/python3.10/dist-packages/discord/http.py", line 359, in request
    raise HTTPException(response, data)
discord.errors.HTTPException: 401 Unauthorized (error code: 0): 401: Unauthorized

The above exception was the direct cause of the following exception:

Traceback (most recent call last):
  File "/root/Doopliss/main.py", line 60, in <module>
    bot.run(TOKEN)
  File "/usr/local/lib/python3.10/dist-packages/discord/client.py", line 717, in run
    return future.result()
  File "/usr/local/lib/python3.10/dist-packages/discord/client.py", line 696, in runner
    await self.start(*args, **kwargs)
  File "/usr/local/lib/python3.10/dist-packages/discord/client.py", line 659, in start
    await self.login(token)
  File "/usr/local/lib/python3.10/dist-packages/discord/client.py", line 514, in login
    data = await self.http.static_login(token.strip())
  File "/usr/local/lib/python3.10/dist-packages/discord/http.py", line 410, in static_login
    raise LoginFailure("Improper token has been passed.") from exc
discord.errors.LoginFailure: Improper token has been passed.
/usr/lib/python3/dist-packages/requests/__init__.py:87: RequestsDependencyWarning: urllib3 (2.0.3) or chardet (4.0.0) doesn't match a supported version!
  warnings.warn("urllib3 ({}) or chardet ({}) doesn't match a supported "
Traceback (most recent call last):
  File "/usr/local/lib/python3.10/dist-packages/discord/http.py", line 406, in static_login
    data = await self.request(Route("GET", "/users/@me"))
  File "/usr/local/lib/python3.10/dist-packages/discord/http.py", line 359, in request
    raise HTTPException(response, data)
discord.errors.HTTPException: 401 Unauthorized (error code: 0): 401: Unauthorized

The above exception was the direct cause of the following exception:

Traceback (most recent call last):
  File "/root/Doopliss/main.py", line 60, in <module>
    bot.run(TOKEN)
  File "/usr/local/lib/python3.10/dist-packages/discord/client.py", line 717, in run
    return future.result()
  File "/usr/local/lib/python3.10/dist-packages/discord/client.py", line 696, in runner
    await self.start(*args, **kwargs)
  File "/usr/local/lib/python3.10/dist-packages/discord/client.py", line 659, in start
    await self.login(token)
  File "/usr/local/lib/python3.10/dist-packages/discord/client.py", line 514, in login
    data = await self.http.static_login(token.strip())
  File "/usr/local/lib/python3.10/dist-packages/discord/http.py", line 410, in static_login
    raise LoginFailure("Improper token has been passed.") from exc
discord.errors.LoginFailure: Improper token has been passed.
/usr/lib/python3/dist-packages/requests/__init__.py:87: RequestsDependencyWarning: urllib3 (2.0.3) or chardet (4.0.0) doesn't match a supported version!
  warnings.warn("urllib3 ({}) or chardet ({}) doesn't match a supported "
Traceback (most recent call last):
  File "/usr/local/lib/python3.10/dist-packages/discord/http.py", line 406, in static_login
    data = await self.request(Route("GET", "/users/@me"))
  File "/usr/local/lib/python3.10/dist-packages/discord/http.py", line 359, in request
    raise HTTPException(response, data)
discord.errors.HTTPException: 401 Unauthorized (error code: 0): 401: Unauthorized

The above exception was the direct cause of the following exception:

Traceback (most recent call last):
  File "/root/Doopliss/main.py", line 60, in <module>
    bot.run(TOKEN)
  File "/usr/local/lib/python3.10/dist-packages/discord/client.py", line 717, in run
    return future.result()
  File "/usr/local/lib/python3.10/dist-packages/discord/client.py", line 696, in runner
    await self.start(*args, **kwargs)
  File "/usr/local/lib/python3.10/dist-packages/discord/client.py", line 659, in start
    await self.login(token)
  File "/usr/local/lib/python3.10/dist-packages/discord/client.py", line 514, in login
    data = await self.http.static_login(token.strip())
  File "/usr/local/lib/python3.10/dist-packages/discord/http.py", line 410, in static_login
    raise LoginFailure("Improper token has been passed.") from exc
discord.errors.LoginFailure: Improper token has been passed.
/usr/lib/python3/dist-packages/requests/__init__.py:87: RequestsDependencyWarning: urllib3 (2.0.3) or chardet (4.0.0) doesn't match a supported version!
  warnings.warn("urllib3 ({}) or chardet ({}) doesn't match a supported "
Traceback (most recent call last):
  File "/usr/local/lib/python3.10/dist-packages/discord/http.py", line 406, in static_login
    data = await self.request(Route("GET", "/users/@me"))
  File "/usr/local/lib/python3.10/dist-packages/discord/http.py", line 359, in request
    raise HTTPException(response, data)
discord.errors.HTTPException: 401 Unauthorized (error code: 0): 401: Unauthorized

The above exception was the direct cause of the following exception:

Traceback (most recent call last):
  File "/root/Doopliss/main.py", line 60, in <module>
    bot.run(TOKEN)
  File "/usr/local/lib/python3.10/dist-packages/discord/client.py", line 717, in run
    return future.result()
  File "/usr/local/lib/python3.10/dist-packages/discord/client.py", line 696, in runner
    await self.start(*args, **kwargs)
  File "/usr/local/lib/python3.10/dist-packages/discord/client.py", line 659, in start
    await self.login(token)
  File "/usr/local/lib/python3.10/dist-packages/discord/client.py", line 514, in login
    data = await self.http.static_login(token.strip())
  File "/usr/local/lib/python3.10/dist-packages/discord/http.py", line 410, in static_login
    raise LoginFailure("Improper token has been passed.") from exc
discord.errors.LoginFailure: Improper token has been passed.
/usr/lib/python3/dist-packages/requests/__init__.py:87: RequestsDependencyWarning: urllib3 (2.0.3) or chardet (4.0.0) doesn't match a supported version!
  warnings.warn("urllib3 ({}) or chardet ({}) doesn't match a supported "
Traceback (most recent call last):
  File "/usr/local/lib/python3.10/dist-packages/discord/http.py", line 406, in static_login
    data = await self.request(Route("GET", "/users/@me"))
  File "/usr/local/lib/python3.10/dist-packages/discord/http.py", line 359, in request
    raise HTTPException(response, data)
discord.errors.HTTPException: 401 Unauthorized (error code: 0): 401: Unauthorized

The above exception was the direct cause of the following exception:

Traceback (most recent call last):
  File "/root/Doopliss/main.py", line 60, in <module>
    bot.run(TOKEN)
  File "/usr/local/lib/python3.10/dist-packages/discord/client.py", line 717, in run
    return future.result()
  File "/usr/local/lib/python3.10/dist-packages/discord/client.py", line 696, in runner
    await self.start(*args, **kwargs)
  File "/usr/local/lib/python3.10/dist-packages/discord/client.py", line 659, in start
    await self.login(token)
  File "/usr/local/lib/python3.10/dist-packages/discord/client.py", line 514, in login
    data = await self.http.static_login(token.strip())
  File "/usr/local/lib/python3.10/dist-packages/discord/http.py", line 410, in static_login
    raise LoginFailure("Improper token has been passed.") from exc
discord.errors.LoginFailure: Improper token has been passed.
/usr/lib/python3/dist-packages/requests/__init__.py:87: RequestsDependencyWarning: urllib3 (2.0.3) or chardet (4.0.0) doesn't match a supported version!
  warnings.warn("urllib3 ({}) or chardet ({}) doesn't match a supported "
Traceback (most recent call last):
  File "/usr/local/lib/python3.10/dist-packages/discord/http.py", line 406, in static_login
    data = await self.request(Route("GET", "/users/@me"))
  File "/usr/local/lib/python3.10/dist-packages/discord/http.py", line 359, in request
    raise HTTPException(response, data)
discord.errors.HTTPException: 401 Unauthorized (error code: 0): 401: Unauthorized

The above exception was the direct cause of the following exception:

Traceback (most recent call last):
  File "/root/Doopliss/main.py", line 60, in <module>
    bot.run(TOKEN)
  File "/usr/local/lib/python3.10/dist-packages/discord/client.py", line 717, in run
    return future.result()
  File "/usr/local/lib/python3.10/dist-packages/discord/client.py", line 696, in runner
    await self.start(*args, **kwargs)
  File "/usr/local/lib/python3.10/dist-packages/discord/client.py", line 659, in start
    await self.login(token)
  File "/usr/local/lib/python3.10/dist-packages/discord/client.py", line 514, in login
    data = await self.http.static_login(token.strip())
  File "/usr/local/lib/python3.10/dist-packages/discord/http.py", line 410, in static_login
    raise LoginFailure("Improper token has been passed.") from exc
discord.errors.LoginFailure: Improper token has been passed.
/usr/lib/python3/dist-packages/requests/__init__.py:87: RequestsDependencyWarning: urllib3 (2.0.3) or chardet (4.0.0) doesn't match a supported version!
  warnings.warn("urllib3 ({}) or chardet ({}) doesn't match a supported "
Traceback (most recent call last):
  File "/usr/local/lib/python3.10/dist-packages/discord/http.py", line 406, in static_login
    data = await self.request(Route("GET", "/users/@me"))
  File "/usr/local/lib/python3.10/dist-packages/discord/http.py", line 359, in request
    raise HTTPException(response, data)
discord.errors.HTTPException: 401 Unauthorized (error code: 0): 401: Unauthorized

The above exception was the direct cause of the following exception:

Traceback (most recent call last):
  File "/root/Doopliss/main.py", line 60, in <module>
    bot.run(TOKEN)
  File "/usr/local/lib/python3.10/dist-packages/discord/client.py", line 717, in run
    return future.result()
  File "/usr/local/lib/python3.10/dist-packages/discord/client.py", line 696, in runner
    await self.start(*args, **kwargs)
  File "/usr/local/lib/python3.10/dist-packages/discord/client.py", line 659, in start
    await self.login(token)
  File "/usr/local/lib/python3.10/dist-packages/discord/client.py", line 514, in login
    data = await self.http.static_login(token.strip())
  File "/usr/local/lib/python3.10/dist-packages/discord/http.py", line 410, in static_login
    raise LoginFailure("Improper token has been passed.") from exc
discord.errors.LoginFailure: Improper token has been passed.
/usr/lib/python3/dist-packages/requests/__init__.py:87: RequestsDependencyWarning: urllib3 (2.0.3) or chardet (4.0.0) doesn't match a supported version!
  warnings.warn("urllib3 ({}) or chardet ({}) doesn't match a supported "
Traceback (most recent call last):
  File "/usr/local/lib/python3.10/dist-packages/discord/http.py", line 406, in static_login
    data = await self.request(Route("GET", "/users/@me"))
  File "/usr/local/lib/python3.10/dist-packages/discord/http.py", line 359, in request
    raise HTTPException(response, data)
discord.errors.HTTPException: 401 Unauthorized (error code: 0): 401: Unauthorized

The above exception was the direct cause of the following exception:

Traceback (most recent call last):
  File "/root/Doopliss/main.py", line 60, in <module>
    bot.run(TOKEN)
  File "/usr/local/lib/python3.10/dist-packages/discord/client.py", line 717, in run
    return future.result()
  File "/usr/local/lib/python3.10/dist-packages/discord/client.py", line 696, in runner
    await self.start(*args, **kwargs)
  File "/usr/local/lib/python3.10/dist-packages/discord/client.py", line 659, in start
    await self.login(token)
  File "/usr/local/lib/python3.10/dist-packages/discord/client.py", line 514, in login
    data = await self.http.static_login(token.strip())
  File "/usr/local/lib/python3.10/dist-packages/discord/http.py", line 410, in static_login
    raise LoginFailure("Improper token has been passed.") from exc
discord.errors.LoginFailure: Improper token has been passed.
/usr/lib/python3/dist-packages/requests/__init__.py:87: RequestsDependencyWarning: urllib3 (2.0.3) or chardet (4.0.0) doesn't match a supported version!
  warnings.warn("urllib3 ({}) or chardet ({}) doesn't match a supported "
Traceback (most recent call last):
  File "/usr/local/lib/python3.10/dist-packages/discord/http.py", line 406, in static_login
    data = await self.request(Route("GET", "/users/@me"))
  File "/usr/local/lib/python3.10/dist-packages/discord/http.py", line 359, in request
    raise HTTPException(response, data)
discord.errors.HTTPException: 401 Unauthorized (error code: 0): 401: Unauthorized

The above exception was the direct cause of the following exception:

Traceback (most recent call last):
  File "/root/Doopliss/main.py", line 60, in <module>
    bot.run(TOKEN)
  File "/usr/local/lib/python3.10/dist-packages/discord/client.py", line 717, in run
    return future.result()
  File "/usr/local/lib/python3.10/dist-packages/discord/client.py", line 696, in runner
    await self.start(*args, **kwargs)
  File "/usr/local/lib/python3.10/dist-packages/discord/client.py", line 659, in start
    await self.login(token)
  File "/usr/local/lib/python3.10/dist-packages/discord/client.py", line 514, in login
    data = await self.http.static_login(token.strip())
  File "/usr/local/lib/python3.10/dist-packages/discord/http.py", line 410, in static_login
    raise LoginFailure("Improper token has been passed.") from exc
discord.errors.LoginFailure: Improper token has been passed.
/usr/lib/python3/dist-packages/requests/__init__.py:87: RequestsDependencyWarning: urllib3 (2.0.3) or chardet (4.0.0) doesn't match a supported version!
  warnings.warn("urllib3 ({}) or chardet ({}) doesn't match a supported "
Traceback (most recent call last):
  File "/usr/local/lib/python3.10/dist-packages/discord/http.py", line 406, in static_login
    data = await self.request(Route("GET", "/users/@me"))
  File "/usr/local/lib/python3.10/dist-packages/discord/http.py", line 359, in request
    raise HTTPException(response, data)
discord.errors.HTTPException: 401 Unauthorized (error code: 0): 401: Unauthorized

The above exception was the direct cause of the following exception:

Traceback (most recent call last):
  File "/root/Doopliss/main.py", line 60, in <module>
    bot.run(TOKEN)
  File "/usr/local/lib/python3.10/dist-packages/discord/client.py", line 717, in run
    return future.result()
  File "/usr/local/lib/python3.10/dist-packages/discord/client.py", line 696, in runner
    await self.start(*args, **kwargs)
  File "/usr/local/lib/python3.10/dist-packages/discord/client.py", line 659, in start
    await self.login(token)
  File "/usr/local/lib/python3.10/dist-packages/discord/client.py", line 514, in login
    data = await self.http.static_login(token.strip())
  File "/usr/local/lib/python3.10/dist-packages/discord/http.py", line 410, in static_login
    raise LoginFailure("Improper token has been passed.") from exc
discord.errors.LoginFailure: Improper token has been passed.
/usr/lib/python3/dist-packages/requests/__init__.py:87: RequestsDependencyWarning: urllib3 (2.0.3) or chardet (4.0.0) doesn't match a supported version!
  warnings.warn("urllib3 ({}) or chardet ({}) doesn't match a supported "
Traceback (most recent call last):
  File "/usr/local/lib/python3.10/dist-packages/discord/http.py", line 406, in static_login
    data = await self.request(Route("GET", "/users/@me"))
  File "/usr/local/lib/python3.10/dist-packages/discord/http.py", line 359, in request
    raise HTTPException(response, data)
discord.errors.HTTPException: 401 Unauthorized (error code: 0): 401: Unauthorized

The above exception was the direct cause of the following exception:

Traceback (most recent call last):
  File "/root/Doopliss/main.py", line 60, in <module>
    bot.run(TOKEN)
  File "/usr/local/lib/python3.10/dist-packages/discord/client.py", line 717, in run
    return future.result()
  File "/usr/local/lib/python3.10/dist-packages/discord/client.py", line 696, in runner
    await self.start(*args, **kwargs)
  File "/usr/local/lib/python3.10/dist-packages/discord/client.py", line 659, in start
    await self.login(token)
  File "/usr/local/lib/python3.10/dist-packages/discord/client.py", line 514, in login
    data = await self.http.static_login(token.strip())
  File "/usr/local/lib/python3.10/dist-packages/discord/http.py", line 410, in static_login
    raise LoginFailure("Improper token has been passed.") from exc
discord.errors.LoginFailure: Improper token has been passed.
/usr/lib/python3/dist-packages/requests/__init__.py:87: RequestsDependencyWarning: urllib3 (2.0.3) or chardet (4.0.0) doesn't match a supported version!
  warnings.warn("urllib3 ({}) or chardet ({}) doesn't match a supported "
Traceback (most recent call last):
  File "/usr/local/lib/python3.10/dist-packages/discord/http.py", line 406, in static_login
    data = await self.request(Route("GET", "/users/@me"))
  File "/usr/local/lib/python3.10/dist-packages/discord/http.py", line 359, in request
    raise HTTPException(response, data)
discord.errors.HTTPException: 401 Unauthorized (error code: 0): 401: Unauthorized

The above exception was the direct cause of the following exception:

Traceback (most recent call last):
  File "/root/Doopliss/main.py", line 60, in <module>
    bot.run(TOKEN)
  File "/usr/local/lib/python3.10/dist-packages/discord/client.py", line 717, in run
    return future.result()
  File "/usr/local/lib/python3.10/dist-packages/discord/client.py", line 696, in runner
    await self.start(*args, **kwargs)
  File "/usr/local/lib/python3.10/dist-packages/discord/client.py", line 659, in start
    await self.login(token)
  File "/usr/local/lib/python3.10/dist-packages/discord/client.py", line 514, in login
    data = await self.http.static_login(token.strip())
  File "/usr/local/lib/python3.10/dist-packages/discord/http.py", line 410, in static_login
    raise LoginFailure("Improper token has been passed.") from exc
discord.errors.LoginFailure: Improper token has been passed.
/usr/lib/python3/dist-packages/requests/__init__.py:87: RequestsDependencyWarning: urllib3 (2.0.3) or chardet (4.0.0) doesn't match a supported version!
  warnings.warn("urllib3 ({}) or chardet ({}) doesn't match a supported "
Traceback (most recent call last):
  File "/usr/local/lib/python3.10/dist-packages/discord/http.py", line 406, in static_login
    data = await self.request(Route("GET", "/users/@me"))
  File "/usr/local/lib/python3.10/dist-packages/discord/http.py", line 359, in request
    raise HTTPException(response, data)
discord.errors.HTTPException: 401 Unauthorized (error code: 0): 401: Unauthorized

The above exception was the direct cause of the following exception:

Traceback (most recent call last):
  File "/root/Doopliss/main.py", line 60, in <module>
    bot.run(TOKEN)
  File "/usr/local/lib/python3.10/dist-packages/discord/client.py", line 717, in run
    return future.result()
  File "/usr/local/lib/python3.10/dist-packages/discord/client.py", line 696, in runner
    await self.start(*args, **kwargs)
  File "/usr/local/lib/python3.10/dist-packages/discord/client.py", line 659, in start
    await self.login(token)
  File "/usr/local/lib/python3.10/dist-packages/discord/client.py", line 514, in login
    data = await self.http.static_login(token.strip())
  File "/usr/local/lib/python3.10/dist-packages/discord/http.py", line 410, in static_login
    raise LoginFailure("Improper token has been passed.") from exc
discord.errors.LoginFailure: Improper token has been passed.
/usr/lib/python3/dist-packages/requests/__init__.py:87: RequestsDependencyWarning: urllib3 (2.0.3) or chardet (4.0.0) doesn't match a supported version!
  warnings.warn("urllib3 ({}) or chardet ({}) doesn't match a supported "
Traceback (most recent call last):
  File "/usr/local/lib/python3.10/dist-packages/discord/http.py", line 406, in static_login
    data = await self.request(Route("GET", "/users/@me"))
  File "/usr/local/lib/python3.10/dist-packages/discord/http.py", line 359, in request
    raise HTTPException(response, data)
discord.errors.HTTPException: 401 Unauthorized (error code: 0): 401: Unauthorized

The above exception was the direct cause of the following exception:

Traceback (most recent call last):
  File "/root/Doopliss/main.py", line 60, in <module>
    bot.run(TOKEN)
  File "/usr/local/lib/python3.10/dist-packages/discord/client.py", line 717, in run
    return future.result()
  File "/usr/local/lib/python3.10/dist-packages/discord/client.py", line 696, in runner
    await self.start(*args, **kwargs)
  File "/usr/local/lib/python3.10/dist-packages/discord/client.py", line 659, in start
    await self.login(token)
  File "/usr/local/lib/python3.10/dist-packages/discord/client.py", line 514, in login
    data = await self.http.static_login(token.strip())
  File "/usr/local/lib/python3.10/dist-packages/discord/http.py", line 410, in static_login
    raise LoginFailure("Improper token has been passed.") from exc
discord.errors.LoginFailure: Improper token has been passed.
/usr/lib/python3/dist-packages/requests/__init__.py:87: RequestsDependencyWarning: urllib3 (2.0.3) or chardet (4.0.0) doesn't match a supported version!
  warnings.warn("urllib3 ({}) or chardet ({}) doesn't match a supported "
Traceback (most recent call last):
  File "/usr/local/lib/python3.10/dist-packages/discord/http.py", line 406, in static_login
    data = await self.request(Route("GET", "/users/@me"))
  File "/usr/local/lib/python3.10/dist-packages/discord/http.py", line 359, in request
    raise HTTPException(response, data)
discord.errors.HTTPException: 401 Unauthorized (error code: 0): 401: Unauthorized

The above exception was the direct cause of the following exception:

Traceback (most recent call last):
  File "/root/Doopliss/main.py", line 60, in <module>
    bot.run(TOKEN)
  File "/usr/local/lib/python3.10/dist-packages/discord/client.py", line 717, in run
    return future.result()
  File "/usr/local/lib/python3.10/dist-packages/discord/client.py", line 696, in runner
    await self.start(*args, **kwargs)
  File "/usr/local/lib/python3.10/dist-packages/discord/client.py", line 659, in start
    await self.login(token)
  File "/usr/local/lib/python3.10/dist-packages/discord/client.py", line 514, in login
    data = await self.http.static_login(token.strip())
  File "/usr/local/lib/python3.10/dist-packages/discord/http.py", line 410, in static_login
    raise LoginFailure("Improper token has been passed.") from exc
discord.errors.LoginFailure: Improper token has been passed.
/usr/lib/python3/dist-packages/requests/__init__.py:87: RequestsDependencyWarning: urllib3 (2.0.3) or chardet (4.0.0) doesn't match a supported version!
  warnings.warn("urllib3 ({}) or chardet ({}) doesn't match a supported "
Traceback (most recent call last):
  File "/usr/local/lib/python3.10/dist-packages/discord/http.py", line 406, in static_login
    data = await self.request(Route("GET", "/users/@me"))
  File "/usr/local/lib/python3.10/dist-packages/discord/http.py", line 359, in request
    raise HTTPException(response, data)
discord.errors.HTTPException: 401 Unauthorized (error code: 0): 401: Unauthorized

The above exception was the direct cause of the following exception:

Traceback (most recent call last):
  File "/root/Doopliss/main.py", line 60, in <module>
    bot.run(TOKEN)
  File "/usr/local/lib/python3.10/dist-packages/discord/client.py", line 717, in run
    return future.result()
  File "/usr/local/lib/python3.10/dist-packages/discord/client.py", line 696, in runner
    await self.start(*args, **kwargs)
  File "/usr/local/lib/python3.10/dist-packages/discord/client.py", line 659, in start
    await self.login(token)
  File "/usr/local/lib/python3.10/dist-packages/discord/client.py", line 514, in login
    data = await self.http.static_login(token.strip())
  File "/usr/local/lib/python3.10/dist-packages/discord/http.py", line 410, in static_login
    raise LoginFailure("Improper token has been passed.") from exc
discord.errors.LoginFailure: Improper token has been passed.
/usr/lib/python3/dist-packages/requests/__init__.py:87: RequestsDependencyWarning: urllib3 (2.0.3) or chardet (4.0.0) doesn't match a supported version!
  warnings.warn("urllib3 ({}) or chardet ({}) doesn't match a supported "
Traceback (most recent call last):
  File "/usr/local/lib/python3.10/dist-packages/discord/http.py", line 406, in static_login
    data = await self.request(Route("GET", "/users/@me"))
  File "/usr/local/lib/python3.10/dist-packages/discord/http.py", line 359, in request
    raise HTTPException(response, data)
discord.errors.HTTPException: 401 Unauthorized (error code: 0): 401: Unauthorized

The above exception was the direct cause of the following exception:

Traceback (most recent call last):
  File "/root/Doopliss/main.py", line 60, in <module>
    bot.run(TOKEN)
  File "/usr/local/lib/python3.10/dist-packages/discord/client.py", line 717, in run
    return future.result()
  File "/usr/local/lib/python3.10/dist-packages/discord/client.py", line 696, in runner
    await self.start(*args, **kwargs)
  File "/usr/local/lib/python3.10/dist-packages/discord/client.py", line 659, in start
    await self.login(token)
  File "/usr/local/lib/python3.10/dist-packages/discord/client.py", line 514, in login
    data = await self.http.static_login(token.strip())
  File "/usr/local/lib/python3.10/dist-packages/discord/http.py", line 410, in static_login
    raise LoginFailure("Improper token has been passed.") from exc
discord.errors.LoginFailure: Improper token has been passed.
/usr/lib/python3/dist-packages/requests/__init__.py:87: RequestsDependencyWarning: urllib3 (2.0.3) or chardet (4.0.0) doesn't match a supported version!
  warnings.warn("urllib3 ({}) or chardet ({}) doesn't match a supported "
Traceback (most recent call last):
  File "/usr/local/lib/python3.10/dist-packages/discord/http.py", line 406, in static_login
    data = await self.request(Route("GET", "/users/@me"))
  File "/usr/local/lib/python3.10/dist-packages/discord/http.py", line 359, in request
    raise HTTPException(response, data)
discord.errors.HTTPException: 401 Unauthorized (error code: 0): 401: Unauthorized

The above exception was the direct cause of the following exception:

Traceback (most recent call last):
  File "/root/Doopliss/main.py", line 60, in <module>
    bot.run(TOKEN)
  File "/usr/local/lib/python3.10/dist-packages/discord/client.py", line 717, in run
    return future.result()
  File "/usr/local/lib/python3.10/dist-packages/discord/client.py", line 696, in runner
    await self.start(*args, **kwargs)
  File "/usr/local/lib/python3.10/dist-packages/discord/client.py", line 659, in start
    await self.login(token)
  File "/usr/local/lib/python3.10/dist-packages/discord/client.py", line 514, in login
    data = await self.http.static_login(token.strip())
  File "/usr/local/lib/python3.10/dist-packages/discord/http.py", line 410, in static_login
    raise LoginFailure("Improper token has been passed.") from exc
discord.errors.LoginFailure: Improper token has been passed.
/usr/lib/python3/dist-packages/requests/__init__.py:87: RequestsDependencyWarning: urllib3 (2.0.3) or chardet (4.0.0) doesn't match a supported version!
  warnings.warn("urllib3 ({}) or chardet ({}) doesn't match a supported "
Traceback (most recent call last):
  File "/usr/local/lib/python3.10/dist-packages/discord/http.py", line 406, in static_login
    data = await self.request(Route("GET", "/users/@me"))
  File "/usr/local/lib/python3.10/dist-packages/discord/http.py", line 359, in request
    raise HTTPException(response, data)
discord.errors.HTTPException: 401 Unauthorized (error code: 0): 401: Unauthorized

The above exception was the direct cause of the following exception:

Traceback (most recent call last):
  File "/root/Doopliss/main.py", line 60, in <module>
    bot.run(TOKEN)
  File "/usr/local/lib/python3.10/dist-packages/discord/client.py", line 717, in run
    return future.result()
  File "/usr/local/lib/python3.10/dist-packages/discord/client.py", line 696, in runner
    await self.start(*args, **kwargs)
  File "/usr/local/lib/python3.10/dist-packages/discord/client.py", line 659, in start
    await self.login(token)
  File "/usr/local/lib/python3.10/dist-packages/discord/client.py", line 514, in login
    data = await self.http.static_login(token.strip())
  File "/usr/local/lib/python3.10/dist-packages/discord/http.py", line 410, in static_login
    raise LoginFailure("Improper token has been passed.") from exc
discord.errors.LoginFailure: Improper token has been passed.
/usr/lib/python3/dist-packages/requests/__init__.py:87: RequestsDependencyWarning: urllib3 (2.0.3) or chardet (4.0.0) doesn't match a supported version!
  warnings.warn("urllib3 ({}) or chardet ({}) doesn't match a supported "
Traceback (most recent call last):
  File "/usr/local/lib/python3.10/dist-packages/discord/http.py", line 406, in static_login
    data = await self.request(Route("GET", "/users/@me"))
  File "/usr/local/lib/python3.10/dist-packages/discord/http.py", line 359, in request
    raise HTTPException(response, data)
discord.errors.HTTPException: 401 Unauthorized (error code: 0): 401: Unauthorized

The above exception was the direct cause of the following exception:

Traceback (most recent call last):
  File "/root/Doopliss/main.py", line 60, in <module>
    bot.run(TOKEN)
  File "/usr/local/lib/python3.10/dist-packages/discord/client.py", line 717, in run
    return future.result()
  File "/usr/local/lib/python3.10/dist-packages/discord/client.py", line 696, in runner
    await self.start(*args, **kwargs)
  File "/usr/local/lib/python3.10/dist-packages/discord/client.py", line 659, in start
    await self.login(token)
  File "/usr/local/lib/python3.10/dist-packages/discord/client.py", line 514, in login
    data = await self.http.static_login(token.strip())
  File "/usr/local/lib/python3.10/dist-packages/discord/http.py", line 410, in static_login
    raise LoginFailure("Improper token has been passed.") from exc
discord.errors.LoginFailure: Improper token has been passed.
Traceback (most recent call last):
  File "/usr/local/lib/python3.10/dist-packages/discord/http.py", line 406, in static_login
    data = await self.request(Route("GET", "/users/@me"))
  File "/usr/local/lib/python3.10/dist-packages/discord/http.py", line 359, in request
    raise HTTPException(response, data)
discord.errors.HTTPException: 401 Unauthorized (error code: 0): 401: Unauthorized

The above exception was the direct cause of the following exception:

Traceback (most recent call last):
  File "/root/Doopliss/main.py", line 60, in <module>
    bot.run(TOKEN)
  File "/usr/local/lib/python3.10/dist-packages/discord/client.py", line 717, in run
    return future.result()
  File "/usr/local/lib/python3.10/dist-packages/discord/client.py", line 696, in runner
    await self.start(*args, **kwargs)
  File "/usr/local/lib/python3.10/dist-packages/discord/client.py", line 659, in start
    await self.login(token)
  File "/usr/local/lib/python3.10/dist-packages/discord/client.py", line 514, in login
    data = await self.http.static_login(token.strip())
  File "/usr/local/lib/python3.10/dist-packages/discord/http.py", line 410, in static_login
    raise LoginFailure("Improper token has been passed.") from exc
discord.errors.LoginFailure: Improper token has been passed.
Traceback (most recent call last):
  File "/usr/local/lib/python3.10/dist-packages/discord/http.py", line 406, in static_login
    data = await self.request(Route("GET", "/users/@me"))
  File "/usr/local/lib/python3.10/dist-packages/discord/http.py", line 359, in request
    raise HTTPException(response, data)
discord.errors.HTTPException: 401 Unauthorized (error code: 0): 401: Unauthorized

The above exception was the direct cause of the following exception:

Traceback (most recent call last):
  File "/root/Doopliss/main.py", line 60, in <module>
    bot.run(TOKEN)
  File "/usr/local/lib/python3.10/dist-packages/discord/client.py", line 717, in run
    return future.result()
  File "/usr/local/lib/python3.10/dist-packages/discord/client.py", line 696, in runner
    await self.start(*args, **kwargs)
  File "/usr/local/lib/python3.10/dist-packages/discord/client.py", line 659, in start
    await self.login(token)
  File "/usr/local/lib/python3.10/dist-packages/discord/client.py", line 514, in login
    data = await self.http.static_login(token.strip())
  File "/usr/local/lib/python3.10/dist-packages/discord/http.py", line 410, in static_login
    raise LoginFailure("Improper token has been passed.") from exc
discord.errors.LoginFailure: Improper token has been passed.
Traceback (most recent call last):
  File "/usr/local/lib/python3.10/dist-packages/discord/http.py", line 406, in static_login
    data = await self.request(Route("GET", "/users/@me"))
  File "/usr/local/lib/python3.10/dist-packages/discord/http.py", line 359, in request
    raise HTTPException(response, data)
discord.errors.HTTPException: 401 Unauthorized (error code: 0): 401: Unauthorized

The above exception was the direct cause of the following exception:

Traceback (most recent call last):
  File "/root/Doopliss/main.py", line 60, in <module>
    bot.run(TOKEN)
  File "/usr/local/lib/python3.10/dist-packages/discord/client.py", line 717, in run
    return future.result()
  File "/usr/local/lib/python3.10/dist-packages/discord/client.py", line 696, in runner
    await self.start(*args, **kwargs)
  File "/usr/local/lib/python3.10/dist-packages/discord/client.py", line 659, in start
    await self.login(token)
  File "/usr/local/lib/python3.10/dist-packages/discord/client.py", line 514, in login
    data = await self.http.static_login(token.strip())
  File "/usr/local/lib/python3.10/dist-packages/discord/http.py", line 410, in static_login
    raise LoginFailure("Improper token has been passed.") from exc
discord.errors.LoginFailure: Improper token has been passed.
Traceback (most recent call last):
  File "/usr/local/lib/python3.10/dist-packages/discord/http.py", line 406, in static_login
    data = await self.request(Route("GET", "/users/@me"))
  File "/usr/local/lib/python3.10/dist-packages/discord/http.py", line 359, in request
    raise HTTPException(response, data)
discord.errors.HTTPException: 401 Unauthorized (error code: 0): 401: Unauthorized

The above exception was the direct cause of the following exception:

Traceback (most recent call last):
  File "/root/Doopliss/main.py", line 60, in <module>
    bot.run(TOKEN)
  File "/usr/local/lib/python3.10/dist-packages/discord/client.py", line 717, in run
    return future.result()
  File "/usr/local/lib/python3.10/dist-packages/discord/client.py", line 696, in runner
    await self.start(*args, **kwargs)
  File "/usr/local/lib/python3.10/dist-packages/discord/client.py", line 659, in start
    await self.login(token)
  File "/usr/local/lib/python3.10/dist-packages/discord/client.py", line 514, in login
    data = await self.http.static_login(token.strip())
  File "/usr/local/lib/python3.10/dist-packages/discord/http.py", line 410, in static_login
    raise LoginFailure("Improper token has been passed.") from exc
discord.errors.LoginFailure: Improper token has been passed.
Traceback (most recent call last):
  File "/usr/local/lib/python3.10/dist-packages/discord/http.py", line 406, in static_login
    data = await self.request(Route("GET", "/users/@me"))
  File "/usr/local/lib/python3.10/dist-packages/discord/http.py", line 359, in request
    raise HTTPException(response, data)
discord.errors.HTTPException: 401 Unauthorized (error code: 0): 401: Unauthorized

The above exception was the direct cause of the following exception:

Traceback (most recent call last):
  File "/root/Doopliss/main.py", line 60, in <module>
    bot.run(TOKEN)
  File "/usr/local/lib/python3.10/dist-packages/discord/client.py", line 717, in run
    return future.result()
  File "/usr/local/lib/python3.10/dist-packages/discord/client.py", line 696, in runner
    await self.start(*args, **kwargs)
  File "/usr/local/lib/python3.10/dist-packages/discord/client.py", line 659, in start
    await self.login(token)
  File "/usr/local/lib/python3.10/dist-packages/discord/client.py", line 514, in login
    data = await self.http.static_login(token.strip())
  File "/usr/local/lib/python3.10/dist-packages/discord/http.py", line 410, in static_login
    raise LoginFailure("Improper token has been passed.") from exc
discord.errors.LoginFailure: Improper token has been passed.
Traceback (most recent call last):
  File "/usr/local/lib/python3.10/dist-packages/discord/http.py", line 406, in static_login
    data = await self.request(Route("GET", "/users/@me"))
  File "/usr/local/lib/python3.10/dist-packages/discord/http.py", line 359, in request
    raise HTTPException(response, data)
discord.errors.HTTPException: 401 Unauthorized (error code: 0): 401: Unauthorized

The above exception was the direct cause of the following exception:

Traceback (most recent call last):
  File "/root/Doopliss/main.py", line 60, in <module>
    bot.run(TOKEN)
  File "/usr/local/lib/python3.10/dist-packages/discord/client.py", line 717, in run
    return future.result()
  File "/usr/local/lib/python3.10/dist-packages/discord/client.py", line 696, in runner
    await self.start(*args, **kwargs)
  File "/usr/local/lib/python3.10/dist-packages/discord/client.py", line 659, in start
    await self.login(token)
  File "/usr/local/lib/python3.10/dist-packages/discord/client.py", line 514, in login
    data = await self.http.static_login(token.strip())
  File "/usr/local/lib/python3.10/dist-packages/discord/http.py", line 410, in static_login
    raise LoginFailure("Improper token has been passed.") from exc
discord.errors.LoginFailure: Improper token has been passed.
Traceback (most recent call last):
  File "/usr/local/lib/python3.10/dist-packages/discord/http.py", line 406, in static_login
    data = await self.request(Route("GET", "/users/@me"))
  File "/usr/local/lib/python3.10/dist-packages/discord/http.py", line 359, in request
    raise HTTPException(response, data)
discord.errors.HTTPException: 401 Unauthorized (error code: 0): 401: Unauthorized

The above exception was the direct cause of the following exception:

Traceback (most recent call last):
  File "/root/Doopliss/main.py", line 60, in <module>
    bot.run(TOKEN)
  File "/usr/local/lib/python3.10/dist-packages/discord/client.py", line 717, in run
    return future.result()
  File "/usr/local/lib/python3.10/dist-packages/discord/client.py", line 696, in runner
    await self.start(*args, **kwargs)
  File "/usr/local/lib/python3.10/dist-packages/discord/client.py", line 659, in start
    await self.login(token)
  File "/usr/local/lib/python3.10/dist-packages/discord/client.py", line 514, in login
    data = await self.http.static_login(token.strip())
  File "/usr/local/lib/python3.10/dist-packages/discord/http.py", line 410, in static_login
    raise LoginFailure("Improper token has been passed.") from exc
discord.errors.LoginFailure: Improper token has been passed.
Traceback (most recent call last):
  File "/usr/local/lib/python3.10/dist-packages/discord/http.py", line 406, in static_login
    data = await self.request(Route("GET", "/users/@me"))
  File "/usr/local/lib/python3.10/dist-packages/discord/http.py", line 359, in request
    raise HTTPException(response, data)
discord.errors.HTTPException: 401 Unauthorized (error code: 0): 401: Unauthorized

The above exception was the direct cause of the following exception:

Traceback (most recent call last):
  File "/root/Doopliss/main.py", line 60, in <module>
    bot.run(TOKEN)
  File "/usr/local/lib/python3.10/dist-packages/discord/client.py", line 717, in run
    return future.result()
  File "/usr/local/lib/python3.10/dist-packages/discord/client.py", line 696, in runner
    await self.start(*args, **kwargs)
  File "/usr/local/lib/python3.10/dist-packages/discord/client.py", line 659, in start
    await self.login(token)
  File "/usr/local/lib/python3.10/dist-packages/discord/client.py", line 514, in login
    data = await self.http.static_login(token.strip())
  File "/usr/local/lib/python3.10/dist-packages/discord/http.py", line 410, in static_login
    raise LoginFailure("Improper token has been passed.") from exc
discord.errors.LoginFailure: Improper token has been passed.
Traceback (most recent call last):
  File "/usr/local/lib/python3.10/dist-packages/discord/http.py", line 406, in static_login
    data = await self.request(Route("GET", "/users/@me"))
  File "/usr/local/lib/python3.10/dist-packages/discord/http.py", line 359, in request
    raise HTTPException(response, data)
discord.errors.HTTPException: 401 Unauthorized (error code: 0): 401: Unauthorized

The above exception was the direct cause of the following exception:

Traceback (most recent call last):
  File "/root/Doopliss/main.py", line 60, in <module>
    bot.run(TOKEN)
  File "/usr/local/lib/python3.10/dist-packages/discord/client.py", line 717, in run
    return future.result()
  File "/usr/local/lib/python3.10/dist-packages/discord/client.py", line 696, in runner
    await self.start(*args, **kwargs)
  File "/usr/local/lib/python3.10/dist-packages/discord/client.py", line 659, in start
    await self.login(token)
  File "/usr/local/lib/python3.10/dist-packages/discord/client.py", line 514, in login
    data = await self.http.static_login(token.strip())
  File "/usr/local/lib/python3.10/dist-packages/discord/http.py", line 410, in static_login
    raise LoginFailure("Improper token has been passed.") from exc
discord.errors.LoginFailure: Improper token has been passed.
Traceback (most recent call last):
  File "/usr/local/lib/python3.10/dist-packages/discord/http.py", line 406, in static_login
    data = await self.request(Route("GET", "/users/@me"))
  File "/usr/local/lib/python3.10/dist-packages/discord/http.py", line 359, in request
    raise HTTPException(response, data)
discord.errors.HTTPException: 401 Unauthorized (error code: 0): 401: Unauthorized

The above exception was the direct cause of the following exception:

Traceback (most recent call last):
  File "/root/Doopliss/main.py", line 60, in <module>
    bot.run(TOKEN)
  File "/usr/local/lib/python3.10/dist-packages/discord/client.py", line 717, in run
    return future.result()
  File "/usr/local/lib/python3.10/dist-packages/discord/client.py", line 696, in runner
    await self.start(*args, **kwargs)
  File "/usr/local/lib/python3.10/dist-packages/discord/client.py", line 659, in start
    await self.login(token)
  File "/usr/local/lib/python3.10/dist-packages/discord/client.py", line 514, in login
    data = await self.http.static_login(token.strip())
  File "/usr/local/lib/python3.10/dist-packages/discord/http.py", line 410, in static_login
    raise LoginFailure("Improper token has been passed.") from exc
discord.errors.LoginFailure: Improper token has been passed.
                                                                
################################################################
 ______                            __    _                     
|_   _ `.                         [  |  (_)                    
  | | `. \  .--.    .--.   _ .--.  | |  __   .--.   .--.       
  | |  | |/ .'`\ \/ .'`\ \[ '/'`\ \| | [  | ( (`\] ( (`\]      
 _| |_.' /| \__. || \__. | | \__/ || |  | |  `'.'.  `'.'.      
|______.'  '.__.'  '.__.'  | ;.__/[___][___][\__) )[\__) )     
                           [__|              \___/  \___/      
                                                                
################################################################
Running as: Doopliss#3068
With Client ID: 592093862823067704

Built With:
Python 3.10.12
Py-Cord 2.2.2
Ignoring exception in command None:
discord.ext.commands.errors.CommandNotFound: Command "verify" is not found
Ignoring exception in command None:
discord.ext.commands.errors.CommandNotFound: Command "verify" is not found
Ignoring exception in command None:
discord.ext.commands.errors.CommandNotFound: Command "verify" is not found
                                                                
################################################################
 ______                            __    _                     
|_   _ `.                         [  |  (_)                    
  | | `. \  .--.    .--.   _ .--.  | |  __   .--.   .--.       
  | |  | |/ .'`\ \/ .'`\ \[ '/'`\ \| | [  | ( (`\] ( (`\]      
 _| |_.' /| \__. || \__. | | \__/ || |  | |  `'.'.  `'.'.      
|______.'  '.__.'  '.__.'  | ;.__/[___][___][\__) )[\__) )     
                           [__|              \___/  \___/      
                                                                
################################################################
Running as: Doopliss#3068
With Client ID: 592093862823067704

Built With:
Python 3.10.12
Py-Cord 2.2.2
Traceback (most recent call last):
  File "/root/Doopliss/main.py", line 17, in <module>
    from cogs.marioparty import MarioParty
ImportError: cannot import name 'MarioParty' from 'cogs.marioparty' (/root/Doopliss/cogs/marioparty.py)
                                                                
################################################################
 ______                            __    _                     
|_   _ `.                         [  |  (_)                    
  | | `. \  .--.    .--.   _ .--.  | |  __   .--.   .--.       
  | |  | |/ .'`\ \/ .'`\ \[ '/'`\ \| | [  | ( (`\] ( (`\]      
 _| |_.' /| \__. || \__. | | \__/ || |  | |  `'.'.  `'.'.      
|______.'  '.__.'  '.__.'  | ;.__/[___][___][\__) )[\__) )     
                           [__|              \___/  \___/      
                                                                
################################################################
Running as: Doopliss#3068
With Client ID: 592093862823067704

Built With:
Python 3.10.12
Py-Cord 2.2.2
Traceback (most recent call last):
  File "/root/Doopliss/main.py", line 17, in <module>
    from cogs.marioparty import MarioParty
ImportError: cannot import name 'MarioParty' from 'cogs.marioparty' (/root/Doopliss/cogs/marioparty.py)
Traceback (most recent call last):
  File "/root/Doopliss/main.py", line 17, in <module>
    from cogs.marioparty import MarioParty
ImportError: cannot import name 'MarioParty' from 'cogs.marioparty' (/root/Doopliss/cogs/marioparty.py)
